<?xml version="1.0" encoding="utf-8"?>
<!-- This URDF was automatically created by SolidWorks to URDF Exporter! Originally created by Stephen Brawner (brawner@gmail.com) 
     Commit Version: 1.6.0-1-g15f4949  Build Version: 1.6.7594.29634
     For more information, please see http://wiki.ros.org/sw_urdf_exporter -->
<robot
  name="URDFAssem2">
  <link
    name="base_link">
    <inertial>
      <origin
        xyz="0.00208470504530124 -0.000236944935244652 0.0800059486867469"
        rpy="0 0 0" />
      <mass
        value="2.64057664091934" />
      <inertia
        ixx="0.0262820884723891"
        ixy="2.69555215232122E-17"
        ixz="-8.74780144678154E-10"
        iyy="0.0305148360761198"
        iyz="1.69720612763207E-18"
        izz="0.0524178305121725" />
    </inertial>
    <visual>
      <origin
        xyz="0 0 0"
        rpy="0 0 0" />
      <geometry>
        <mesh
          filename="package://URDFAssem2/meshes/base_link.STL" />
      </geometry>
      <material
        name="">
        <color
          rgba="0.647058823529412 0.619607843137255 0.588235294117647 1" />
      </material>
    </visual>
    <collision>
      <origin
        xyz="0 0 0"
        rpy="0 0 0" />
      <geometry>
        <mesh
          filename="package://URDFAssem2/meshes/base_link.STL" />
      </geometry>
    </collision>
  </link>
  <link
    name="WR_link">
    <inertial>
      <origin
        xyz="4.20128341838133E-18 0.0382135054134345 -1.38777878078145E-17"
        rpy="0 0 0" />
      <mass
        value="0.659446300008721" />
      <inertia
        ixx="0.00103103838200959"
        ixy="6.75029427341629E-20"
        ixz="-2.2389835307371E-19"
        iyy="0.00190754760746418"
        iyz="-6.15130681378243E-20"
        izz="0.00103103838200959" />
    </inertial>
    <visual>
      <origin
        xyz="0 0 0"
        rpy="0 0 0" />
      <geometry>
        <mesh
          filename="package://URDFAssem2/meshes/WR_link.STL" />
      </geometry>
      <material
        name="">
        <color
          rgba="0.294117647058824 0.294117647058824 0.294117647058824 1" />
      </material>
    </visual>
    <collision>
      <origin
        xyz="0 0 0"
        rpy="0 0 0" />
      <geometry>
        <mesh
          filename="package://URDFAssem2/meshes/WR_link.STL" />
      </geometry>
    </collision>
  </link>
  <joint
    name="WR_link"
    type="continuous">
    <origin
      xyz="0.00018599 0.15827 0.075"
      rpy="0 0 0" />
    <parent
      link="base_link" />
    <child
      link="WR_link" />
    <axis
      xyz="0 -1 0" />
    <limit
      lower="0"
      upper="0"
      effort="0"
      velocity="0" />
  </joint>
  <link
    name="WL_link">
    <inertial>
      <origin
        xyz="-4.17688886950041E-17 -0.0382135054134346 8.32667268468867E-17"
        rpy="0 0 0" />
      <mass
        value="0.659446300008721" />
      <inertia
        ixx="0.00103103838200959"
        ixy="7.36016516636654E-20"
        ixz="1.66977987172404E-19"
        iyy="0.00190754760746418"
        iyz="-5.66425648346361E-20"
        izz="0.00103103838200959" />
    </inertial>
    <visual>
      <origin
        xyz="0 0 0"
        rpy="0 0 0" />
      <geometry>
        <mesh
          filename="package://URDFAssem2/meshes/WL_link.STL" />
      </geometry>
      <material
        name="">
        <color
          rgba="0.294117647058824 0.294117647058824 0.294117647058824 1" />
      </material>
    </visual>
    <collision>
      <origin
        xyz="0 0 0"
        rpy="0 0 0" />
      <geometry>
        <mesh
          filename="package://URDFAssem2/meshes/WL_link.STL" />
      </geometry>
    </collision>
  </link>
  <joint
    name="WL_link"
    type="continuous">
    <origin
      xyz="0.00018599 -0.15737 0.075"
      rpy="0 0 0" />
    <parent
      link="base_link" />
    <child
      link="WL_link" />
    <axis
      xyz="0 1 0" />
    <limit
      lower="0"
      upper="0"
      effort="0"
      velocity="0" />
  </joint>
  <link
    name="camera_link">
    <inertial>
      <origin
        xyz="-0.017653824464481 0.00131903724453735 0.000694910126294856"
        rpy="0 0 0" />
      <mass
        value="0.0624348084678499" />
      <inertia
        ixx="0.000123910252090277"
        ixy="2.51197166149138E-07"
        ixz="1.34074290038212E-07"
        iyy="1.74977055396427E-05"
        iyz="1.65109976286423E-06"
        izz="0.0001103344902272" />
    </inertial>
    <visual>
      <origin
        xyz="0 0 0"
        rpy="0 0 0" />
      <geometry>
        <mesh
          filename="package://URDFAssem2/meshes/camera_link.STL" />
      </geometry>
      <material
        name="">
        <color
          rgba="0.109803921568627 0.109803921568627 0.109803921568627 1" />
      </material>
    </visual>
    <collision>
      <origin
        xyz="0 0 0"
        rpy="0 0 0" />
      <geometry>
        <mesh
          filename="package://URDFAssem2/meshes/camera_link.STL" />
      </geometry>
    </collision>
  </link>
  <joint
    name="camera_link"
    type="fixed">
    <origin
      xyz="0.12987 0.045247 0.18325"
      rpy="0 0 0" />
    <parent
      link="base_link" />
    <child
      link="camera_link" />
    <axis
      xyz="0 0 0" />
  </joint>
</robot>